Workbook
Name NativeTimeline_Date: #N/A
Name Slicer_Category: #N/A
Name Slicer_Region: #N/A

Sheet Project Instructions
A1: PR. Final Project - "Data Intelligence Dashboard"
A2: Dataset: Use the 'Final Project Dataset' sheet containing 200+ records of customer transactions.
A4: Objective:
A5: Create a full-fledged analysis and reporting solution using Excel to analyze customer transactions, find insights,
A6: and build visualizations and dashboards.
A8: Key Topics to Implement:
A9: - Date & Time Functions: TODAY, NOW, DATEDIF, EOMONTH
A10: - FILTER Function for multi-value returns
A11: - Conditional Formatting with Icons/Arrows
A12: - Create Timestamp (using NOW and iterative calculations)
A13: WHAT-IF Analysis: Scenario Manager, Goal Seek
A14: - Linear Regression using Data Analysis Toolpak
... A30: - Use of all required formulas and functions as listed above

Sheet Final Project Dataset
A1: Transaction_ID | B1: Date | C1: Customer_ID | D1: Customer_Name | E1: Product_ID | F1: Product_Name | G1: Category | H1: Quantity | I1: Unit_Price | J1: Payment_Method | K1: Region | L1: Customer_Segment | M1: Customer_Since | N1: Total_Amount
A2: TRX0155 | B2: 45393 | C2: CUST023 | D2: Paul Baker | E2: P009 | F2: Monitor | G2: Electronics | H2: 3 | I2: 249.99 | J2: Cash | K2: Central | L2: Basic | M2: 44425 | N2: 749.97
A3: TRX0023 | B3: 45396 | C3: CUST013 | D3: Joseph Jackson | E3: P009 | F3: Monitor | G3: Electronics | H3: 3 | I3: 249.99 | J3: Credit Card | K3: Central | L3: Premium | M3: 44575 | N3: 749.97
A4: TRX0139 | B4: 45399 | C4: CUST021 | D4: Kevin Scott | E4: P005 | F4: Blender | G4: Appliances | H4: 3 | I4: 59.99 | J4: PayPal | K4: South | L4: Standard | M4: 45262 | N4: 179.97
A5: TRX0043 | B5: 45400 | C5: CUST046 | D5: Kathleen Bennett | E5: P005 | F5: Blender | G5: Appliances | H5: 3 | I5: 59.99 | J5: Cash | K5: North | L5: Premium | M5: 45114 | N5: 179.97
A6: TRX0212 | B6: 45400 | C6: CUST003 | D6: Michael Brown | E6: P008 | F6: Bookshelf | G6: Furniture | H6: 5 | I6: 149.99 | J6: Credit Card | K6: North | L6: Premium | M6: 45295 | N6: 749.95
A7: TRX0092 | B7: 45403 | C7: CUST024 | D7: Dorothy Nelson | E7: P005 | F7: Blender | G7: Appliances | H7: 2 | I7: 59.99 | J7: Cash | K7: West | L7: Standard | M7: 44746 | N7: 119.98
A8: TRX0193 | B8: 45403 | C8: CUST024 | D8: Dorothy Nelson | E8: P003 | F8: Headphones | G8: Electronics | H8: 5 | I8: 149.99 | J8: Credit Card | K8: Central | L8: Standard | M8: 44418 | N8: 749.95
A9: TRX0240 | B9: 45403 | C9: CUST017 | D9: Charles Allen | E9: P005 | F9: Blender | G9: Appliances | H9: 3 | I9: 59.99 | J9: Debit Card | K9: South | L9: Basic | M9: 45007 | N9: 179.97
A10: TRX0135 | B10: 45405 | C10: CUST009 | D10: Robert Thomas | E10: P001 | F10: Laptop | G10: Electronics | H10: 3 | I10: 899.99 | J10: PayPal | K10: East | L10: Standard | M10: 45299 | N10: 2699.97
A11: TRX0185 | B11: 45408 | C11: CUST026 | D11: Karen Hill | E11: P005 | F11: Blender | G11: Appliances | H11: 3 | I11: 59.99 | J11: Cash | K11: West | L11: Premium | M11: 45207 | N11: 179.97
A12: TRX0138 | B12: 45408 | C12: CUST022 | D12: Susan Green | E12: P008 | F12: Bookshelf | G12: Furniture | H12: 1 | I12: 149.99 | J12: Credit Card | K12: West | L12: Standard | M12: 45103 | N12: 149.99
A13: TRX0209 | B13: 45408 | C13: CUST046 | D13: Kathleen Bennett | E13: P008 | F13: Bookshelf | G13: Furniture | H13: 5 | I13: 149.99 | J13: Debit Card | K13: North | L13: Basic | M13: 44830 | N13: 749.95
... A251: TRX0064 | B251: 45758 | C251: CUST031 | D251: Steven Turner | E251: P010 | F251: Keyboard | G251: Electronics | H251: 3 | I251: 89.99 | J251: Debit Card | K251: North | L251: Premium | M251: 44878 | N251: 269.97

Sheet Task_1_DT
A1: Function | B1: Formula
A2: TODAY | B2: =TODAY() -> 46171
A3: NOW | B3: =NOW() -> 46171.71
A4: Current Year | B4: =YEAR(TODAY()) -> 2026
A5: Current Month | B5: =MONTH(TODAY()) -> 5
A6: Formatted Date | B6: =TEXT(TODAY(),"DD-MMM-YYYY") -> 29-May-2026
A7: Formatted Time | B7: =TEXT(NOW(),"HH:MM AM/PM") -> 05:03 PM
A10: Customer_ID | B10: Customer_Name | C10: Customer_Since | D10: TODAY | E10: DATEDIF | F10: DATEDIF Months | G10: DATEDIF Days | H10: DATEDIF Year and Months
A11: ='Final Project Dataset'!C2 -> CUST023 | B11: ='Final Project Dataset'!D2 -> Paul Baker | C11: ='Final Project Dataset'!M2 -> 44425 | D11: =TODAY() -> 46171 | E11: =DATEDIF(C11,D11,"Y") -> 4 | F11: =DATEDIF(C11,D11,"M") -> 57 | G11: =DATEDIF(C11,D11,"D") -> 1746 | H11: =E11&" Yrs, "&DATEDIF(C11,D11,"YM")&" Months" -> 4 Yrs, 9 Months
A12: ='Final Project Dataset'!C3 -> CUST013 | B12: ='Final Project Dataset'!D3 -> Joseph Jackson | C12: ='Final Project Dataset'!M3 -> 44575 | D12: =TODAY() -> 46171 | E12: =DATEDIF(C12,D12,"Y") -> 4 | F12: =DATEDIF(C12,D12,"M") -> 52 | G12: =DATEDIF(C12,D12,"D") -> 1596 | H12: =E12&" Yrs, "&DATEDIF(C12,D12,"YM")&" Months" -> 4 Yrs, 4 Months
A13: ='Final Project Dataset'!C4 -> CUST021 | B13: ='Final Project Dataset'!D4 -> Kevin Scott | C13: ='Final Project Dataset'!M4 -> 45262 | D13: =TODAY() -> 46171 | E13: =DATEDIF(C13,D13,"Y") -> 2 | F13: =DATEDIF(C13,D13,"M") -> 29 | G13: =DATEDIF(C13,D13,"D") -> 909 | H13: =E13&" Yrs, "&DATEDIF(C13,D13,"YM")&" Months" -> 2 Yrs, 5 Months
A14: ='Final Project Dataset'!C5 -> CUST046 | B14: ='Final Project Dataset'!D5 -> Kathleen Bennett | C14: ='Final Project Dataset'!M5 -> 45114 | D14: =TODAY() -> 46171 | E14: =DATEDIF(C14,D14,"Y") -> 2 | F14: =DATEDIF(C14,D14,"M") -> 34 | G14: =DATEDIF(C14,D14,"D") -> 1057 | H14: =E14&" Yrs, "&DATEDIF(C14,D14,"YM")&" Months" -> 2 Yrs, 10 Months
A15: ='Final Project Dataset'!C6 -> CUST003 | B15: ='Final Project Dataset'!D6 -> Michael Brown | C15: ='Final Project Dataset'!M6 -> 45295 | D15: =TODAY() -> 46171 | E15: =DATEDIF(C15,D15,"Y") -> 2 | F15: =DATEDIF(C15,D15,"M") -> 28 | G15: =DATEDIF(C15,D15,"D") -> 876 | H15: =E15&" Yrs, "&DATEDIF(C15,D15,"YM")&" Months" -> 2 Yrs, 4 Months
A16: ='Final Project Dataset'!C7 -> CUST024 | B16: ='Final Project Dataset'!D7 -> Dorothy Nelson | C16: ='Final Project Dataset'!M7 -> 44746 | D16: =TODAY() -> 46171 | E16: =DATEDIF(C16,D16,"Y") -> 3 | F16: =DATEDIF(C16,D16,"M") -> 46 | G16: =DATEDIF(C16,D16,"D") -> 1425 | H16: =E16&" Yrs, "&DATEDIF(C16,D16,"YM")&" Months" -> 3 Yrs, 10 Months
A17: ='Final Project Dataset'!C8 -> CUST024 | B17: ='Final Project Dataset'!D8 -> Dorothy Nelson | C17: ='Final Project Dataset'!M8 -> 44418 | D17: =TODAY() -> 46171 | E17: =DATEDIF(C17,D17,"Y") -> 4 | F17: =DATEDIF(C17,D17,"M") -> 57 | G17: =DATEDIF(C17,D17,"D") -> 1753 | H17: =E17&" Yrs, "&DATEDIF(C17,D17,"YM")&" Months" -> 4 Yrs, 9 Months
A18: ='Final Project Dataset'!C9 -> CUST017 | B18: ='Final Project Dataset'!D9 -> Charles Allen | C18: ='Final Project Dataset'!M9 -> 45007 | D18: =TODAY() -> 46171 | E18: =DATEDIF(C18,D18,"Y") -> 3 | F18: =DATEDIF(C18,D18,"M") -> 38 | G18: =DATEDIF(C18,D18,"D") -> 1164 | H18: =E18&" Yrs, "&DATEDIF(C18,D18,"YM")&" Months" -> 3 Yrs, 2 Months
A19: ='Final Project Dataset'!C10 -> CUST009 | B19: ='Final Project Dataset'!D10 -> Robert Thomas | C19: ='Final Project Dataset'!M10 -> 45299 | D19: =TODAY() -> 46171 | E19: =DATEDIF(C19,D19,"Y") -> 2 | F19: =DATEDIF(C19,D19,"M") -> 28 | G19: =DATEDIF(C19,D19,"D") -> 872 | H19: =E19&" Yrs, "&DATEDIF(C19,D19,"YM")&" Months" -> 2 Yrs, 4 Months
A20: ='Final Project Dataset'!C11 -> CUST026 | B20: ='Final Project Dataset'!D11 -> Karen Hill | C20: ='Final Project Dataset'!M11 -> 45207 | D20: =TODAY() -> 46171 | E20: =DATEDIF(C20,D20,"Y") -> 2 | F20: =DATEDIF(C20,D20,"M") -> 31 | G20: =DATEDIF(C20,D20,"D") -> 964 | H20: =E20&" Yrs, "&DATEDIF(C20,D20,"YM")&" Months" -> 2 Yrs, 7 Months
A23: Description | B23: Result
A24: End of Current Month | B24: =EOMONTH(TODAY(),0) -> 46173
A25: End of Next Month | B25: =EOMONTH(TODAY(),1) -> 46203
A26: End of Previous Month | B26: =EOMONTH(TODAY(),-1) -> 46142
A27: Start of Current Month | B27: =EOMONTH(TODAY(),-1)+1 -> 46143
A28: Days Left in Month | B28: =EOMONTH(TODAY(),0)-TODAY() -> 2
A29: Last Transaction Month End | B29: =EOMONTH(MAX('Final Project Dataset'!B2:B251),0) -> 45777
A30: First Transaction Month End | B30: =EOMONTH(MIN('Final Project Dataset'!B2:B251),0) -> 45412
A33: Txn_ID | B33: Txn_Date | C33: Today | D33: Days Since Txn | E33: Months Since | F33: End of Txn Month | G33: Year | H33: Month Name
A34: ='Final Project Dataset'!A2 -> TRX0155 | B34: ='Final Project Dataset'!B2 -> 45393 | C34: =TODAY() -> 46171 | D34: =DATEDIF(B34,C34,"D") -> 778 | E34: =DATEDIF(B34,C34,"M") -> 25 | F34: =EOMONTH(B34,0) -> 45412 | G34: =YEAR(B34) -> 2024 | H34: =TEXT(B34,"MMMM") -> April
A35: ='Final Project Dataset'!A3 -> TRX0023 | B35: ='Final Project Dataset'!B3 -> 45396 | C35: =TODAY() -> 46171 | D35: =DATEDIF(B35,C35,"D") -> 775 | E35: =DATEDIF(B35,C35,"M") -> 25 | F35: =EOMONTH(B35,0) -> 45412 | G35: =YEAR(B35) -> 2024 | H35: =TEXT(B35,"MMMM") -> April
A36: ='Final Project Dataset'!A4 -> TRX0139 | B36: ='Final Project Dataset'!B4 -> 45399 | C36: =TODAY() -> 46171 | D36: =DATEDIF(B36,C36,"D") -> 772 | E36: =DATEDIF(B36,C36,"M") -> 25 | F36: =EOMONTH(B36,0) -> 45412 | G36: =YEAR(B36) -> 2024 | H36: =TEXT(B36,"MMMM") -> April
A37: ='Final Project Dataset'!A5 -> TRX0043 | B37: ='Final Project Dataset'!B5 -> 45400 | C37: =TODAY() -> 46171 | D37: =DATEDIF(B37,C37,"D") -> 771 | E37: =DATEDIF(B37,C37,"M") -> 25 | F37: =EOMONTH(B37,0) -> 45412 | G37: =YEAR(B37) -> 2024 | H37: =TEXT(B37,"MMMM") -> April
A38: ='Final Project Dataset'!A6 -> TRX0212 | B38: ='Final Project Dataset'!B6 -> 45400 | C38: =TODAY() -> 46171 | D38: =DATEDIF(B38,C38,"D") -> 771 | E38: =DATEDIF(B38,C38,"M") -> 25 | F38: =EOMONTH(B38,0) -> 45412 | G38: =YEAR(B38) -> 2024 | H38: =TEXT(B38,"MMMM") -> April

Sheet Task_2_Fltr
A1: Transaction_ID | B1: Date | C1: Customer_ID | D1: Customer_Name | E1: Product_ID | F1: Product_Name | G1: Category | H1: Quantity | I1: Unit_Price | J1: Payment_Method | K1: Region | L1: Customer_Segment | M1: Customer_Since | N1: Total_Amount
D2: Filter 1: Electronics Category
A3: {=_xlfn._xlws.FILTER('Final Project Dataset'!A2:N251,'Final Project Dataset'!G2:G251="Electronics")} -> TRX0155 | B3: 45393 | C3: CUST023 | D3: Paul Baker | E3: P009 | F3: Monitor | G3: Electronics | H3: 3 | I3: 249.99 | J3: Cash | K3: Central | L3: Basic | M3: 44425 | N3: 749.97
A4: TRX0023 | B4: 45396 | C4: CUST013 | D4: Joseph Jackson | E4: P009 | F4: Monitor | G4: Electronics | H4: 3 | I4: 249.99 | J4: Credit Card | K4: Central | L4: Premium | M4: 44575 | N4: 749.97
A5: TRX0193 | B5: 45403 | C5: CUST024 | D5: Dorothy Nelson | E5: P003 | F5: Headphones | G5: Electronics | H5: 5 | I5: 149.99 | J5: Credit Card | K5: Central | L5: Standard | M5: 44418 | N5: 749.95
A6: TRX0135 | B6: 45405 | C6: CUST009 | D6: Robert Thomas | E6: P001 | F6: Laptop | G6: Electronics | H6: 3 | I6: 899.99 | J6: PayPal | K6: East | L6: Standard | M6: 45299 | N6: 2699.97
A7: TRX0191 | B7: 45409 | C7: CUST038 | D7: Michelle Rogers | E7: P002 | F7: Smartphone | G7: Electronics | H7: 3 | I7: 699.99 | J7: Credit Card | K7: West | L7: Basic | M7: 44577 | N7: 2099.97
A8: TRX0230 | B8: 45409 | C8: CUST027 | D8: George Adams | E8: P001 | F8: Laptop | G8: Electronics | H8: 1 | I8: 899.99 | J8: Debit Card | K8: North | L8: Standard | M8: 44920 | N8: 899.99
A9: TRX0134 | B9: 45410 | C9: CUST010 | D9: Maria Garcia | E9: P002 | F9: Smartphone | G9: Electronics | H9: 2 | I9: 699.99 | J9: Cash | K9: North | L9: Basic | M9: 44781 | N9: 1399.98
A10: TRX0122 | B10: 45410 | C10: CUST025 | D10: Mark Carter | E10: P001 | F10: Laptop | G10: Electronics | H10: 4 | I10: 899.99 | J10: Credit Card | K10: West | L10: Standard | M10: 45327 | N10: 3599.96
A11: TRX0222 | B11: 45410 | C11: CUST048 | D11: Virginia Sanders | E11: P009 | F11: Monitor | G11: Electronics | H11: 3 | I11: 249.99 | J11: Credit Card | K11: North | L11: Premium | M11: 45224 | N11: 749.97
A12: TRX0231 | B12: 45412 | C12: CUST018 | D12: Barbara Young | E12: P002 | F12: Smartphone | G12: Electronics | H12: 5 | I12: 699.99 | J12: Cash | K12: West | L12: Basic | M12: 45167 | N12: 3499.95
A13: TRX0239 | B13: 45413 | C13: CUST012 | D13: Patricia Moore | E13: P002 | F13: Smartphone | G13: Electronics | H13: 4 | I13: 699.99 | J13: Cash | K13: East | L13: Standard | M13: 44409 | N13: 2799.96
A14: TRX0204 | B14: 45415 | C14: CUST044 | D14: Cynthia Price | E14: P009 | F14: Monitor | G14: Electronics | H14: 4 | I14: 249.99 | J14: PayPal | K14: North | L14: Standard | M14: 44468 | N14: 999.96
A15: TRX0071 | B15: 45422 | C15: CUST036 | D15: Nancy Collins | E15: P009 | F15: Monitor | G15: Electronics | H15: 5 | I15: 249.99 | J15: Credit Card | K15: West | L15: Standard | M15: 44525 | N15: 1249.95
... A133: TRX0064 | B133: 45758 | C133: CUST031 | D133: Steven Turner | E133: P010 | F133: Keyboard | G133: Electronics | H133: 3 | I133: 89.99 | J133: Debit Card | K133: North | L133: Premium | M133: 44878 | N133: 269.97
D136: Filter 2: Premium Customers
A137: {=_xlfn._xlws.FILTER('Final Project Dataset'!A2:N251,'Final Project Dataset'!L2:L251="Premium")} -> TRX0023 | B137: 45396 | C137: CUST013 | D137: Joseph Jackson | E137: P009 | F137: Monitor | G137: Electronics | H137: 3 | I137: 249.99 | J137: Credit Card | K137: Central | L137: Premium | M137: 44575 | N137: 749.97
A138: TRX0043 | B138: 45400 | C138: CUST046 | D138: Kathleen Bennett | E138: P005 | F138: Blender | G138: Appliances | H138: 3 | I138: 59.99 | J138: Cash | K138: North | L138: Premium | M138: 45114 | N138: 179.97
A139: TRX0212 | B139: 45400 | C139: CUST003 | D139: Michael Brown | E139: P008 | F139: Bookshelf | G139: Furniture | H139: 5 | I139: 149.99 | J139: Credit Card | K139: North | L139: Premium | M139: 45295 | N139: 749.95
A140: TRX0185 | B140: 45408 | C140: CUST026 | D140: Karen Hill | E140: P005 | F140: Blender | G140: Appliances | H140: 3 | I140: 59.99 | J140: Cash | K140: West | L140: Premium | M140: 45207 | N140: 179.97
A141: TRX0246 | B141: 45408 | C141: CUST041 | D141: Peter Richardson | E141: P008 | F141: Bookshelf | G141: Furniture | H141: 3 | I141: 149.99 | J141: Cash | K141: North | L141: Premium | M141: 44806 | N141: 449.97
A142: TRX0049 | B142: 45410 | C142: CUST025 | D142: Mark Carter | E142: P008 | F142: Bookshelf | G142: Furniture | H142: 4 | I142: 149.99 | J142: Debit Card | K142: North | L142: Premium | M142: 45374 | N142: 599.96
A143: TRX0222 | B143: 45410 | C143: CUST048 | D143: Virginia Sanders | E143: P009 | F143: Monitor | G143: Electronics | H143: 3 | I143: 249.99 | J143: Credit Card | K143: North | L143: Premium | M143: 45224 | N143: 749.97
A144: TRX0242 | B144: 45416 | C144: CUST025 | D144: Mark Carter | E144: P007 | F144: Desk | G144: Furniture | H144: 4 | I144: 299.99 | J144: Cash | K144: West | L144: Premium | M144: 44716 | N144: 1199.96
A145: TRX0235 | B145: 45424 | C145: CUST014 | D145: Linda Martin | E145: P004 | F145: Coffee Maker | G145: Appliances | H145: 3 | I145: 79.99 | J145: PayPal | K145: East | L145: Premium | M145: 45012 | N145: 239.97
A146: TRX0004 | B146: 45424 | C146: CUST012 | D146: Patricia Moore | E146: P010 | F146: Keyboard | G146: Electronics | H146: 5 | I146: 89.99 | J146: Cash | K146: North | L146: Premium | M146: 44919 | N146: 449.95
A147: TRX0130 | B147: 45430 | C147: CUST002 | D147: Emma Wilson | E147: P008 | F147: Bookshelf | G147: Furniture | H147: 3 | I147: 149.99 | J147: Credit Card | K147: West | L147: Premium | M147: 45068 | N147: 449.97
A148: TRX0041 | B148: 45432 | C148: CUST021 | D148: Kevin Scott | E148: P001 | F148: Laptop | G148: Electronics | H148: 1 | I148: 899.99 | J148: Credit Card | K148: West | L148: Premium | M148: 44578 | N148: 899.99
A149: TRX0245 | B149: 45438 | C149: CUST031 | D149: Steven Turner | E149: P006 | F149: Office Chair | G149: Furniture | H149: 3 | I149: 199.99 | J149: Credit Card | K149: North | L149: Premium | M149: 45292 | N149: 599.97
... A231: TRX0064 | B231: 45758 | C231: CUST031 | D231: Steven Turner | E231: P010 | F231: Keyboard | G231: Electronics | H231: 3 | I231: 89.99 | J231: Debit Card | K231: North | L231: Premium | M231: 44878 | N231: 269.97

Sheet Task_3_CF
A1: Transaction_ID | B1: Date | C1: Customer_ID | D1: Customer_Name | E1: Product_ID | F1: Product_Name | G1: Category | H1: Quantity | I1: Unit_Price | J1: Payment_Method | K1: Region | L1: Customer_Segment | M1: Customer_Since | N1: Total_Amount
A2: TRX0155 | B2: 45393 | C2: CUST023 | D2: Paul Baker | E2: P009 | F2: Monitor | G2: Electronics | H2: 3 | I2: 249.99 | J2: Cash | K2: Central | L2: Basic | M2: 44425 | N2: 749.97
A3: TRX0023 | B3: 45396 | C3: CUST013 | D3: Joseph Jackson | E3: P009 | F3: Monitor | G3: Electronics | H3: 3 | I3: 249.99 | J3: Credit Card | K3: Central | L3: Premium | M3: 44575 | N3: 749.97 | Q3: Color | R3: Conditional | S3: Meaning
A4: TRX0139 | B4: 45399 | C4: CUST021 | D4: Kevin Scott | E4: P005 | F4: Blender | G4: Appliances | H4: 3 | I4: 59.99 | J4: PayPal | K4: South | L4: Standard | M4: 45262 | N4: 179.97 | Q4: Green | R4: Total Amount > 2000 | S4: High Value Transactions
A5: TRX0043 | B5: 45400 | C5: CUST046 | D5: Kathleen Bennett | E5: P005 | F5: Blender | G5: Appliances | H5: 3 | I5: 59.99 | J5: Cash | K5: North | L5: Premium | M5: 45114 | N5: 179.97 | Q5: Purple | R5: Category = Electronics | S5: Electronics Products
A6: TRX0212 | B6: 45400 | C6: CUST003 | D6: Michael Brown | E6: P008 | F6: Bookshelf | G6: Furniture | H6: 5 | I6: 149.99 | J6: Credit Card | K6: North | L6: Premium | M6: 45295 | N6: 749.95 | Q6: Yellow | R6: Customer Segment = Standard | S6: Standard Customers
A7: TRX0092 | B7: 45403 | C7: CUST024 | D7: Dorothy Nelson | E7: P005 | F7: Blender | G7: Appliances | H7: 2 | I7: 59.99 | J7: Cash | K7: West | L7: Standard | M7: 44746 | N7: 119.98 | Q7: Red/Pink | R7: Customer Segment = Basic | S7: Basic Customers
A8: TRX0193 | B8: 45403 | C8: CUST024 | D8: Dorothy Nelson | E8: P003 | F8: Headphones | G8: Electronics | H8: 5 | I8: 149.99 | J8: Credit Card | K8: Central | L8: Standard | M8: 44418 | N8: 749.95 | Q8: Light Green | R8: Top 10 Total Amount | S8: Highest 10 Transactions
A9: TRX0240 | B9: 45403 | C9: CUST017 | D9: Charles Allen | E9: P005 | F9: Blender | G9: Appliances | H9: 3 | I9: 59.99 | J9: Debit Card | K9: South | L9: Basic | M9: 45007 | N9: 179.97 | Q9: No Color | R9: Category = Furniture/Appliances & Segment =Premium | S9: PremiumOther Categories
A10: TRX0135 | B10: 45405 | C10: CUST009 | D10: Robert Thomas | E10: P001 | F10: Laptop | G10: Electronics | H10: a | I10: 899.99 | J10: PayPal | K10: East | L10: Standard | M10: 45299 | N10: 2699.97
A11: TRX0185 | B11: 45408 | C11: CUST026 | D11: Karen Hill | E11: P005 | F11: Blender | G11: Appliances | H11: 3 | I11: 59.99 | J11: Cash | K11: West | L11: Premium | M11: 45207 | N11: 179.97
A12: TRX0138 | B12: 45408 | C12: CUST022 | D12: Susan Green | E12: P008 | F12: Bookshelf | G12: Furniture | H12: 1 | I12: 149.99 | J12: Credit Card | K12: West | L12: Standard | M12: 45103 | N12: 149.99
A13: TRX0209 | B13: 45408 | C13: CUST046 | D13: Kathleen Bennett | E13: P008 | F13: Bookshelf | G13: Furniture | H13: 5 | I13: 149.99 | J13: Debit Card | K13: North | L13: Basic | M13: 44830 | N13: 749.95
A14: TRX0246 | B14: 45408 | C14: CUST041 | D14: Peter Richardson | E14: P008 | F14: Bookshelf | G14: Furniture | H14: 3 | I14: 149.99 | J14: Cash | K14: North | L14: Premium | M14: 44806 | N14: 449.97
A15: TRX0067 | B15: 45409 | C15: CUST043 | D15: Dennis Gray | E15: P005 | F15: Blender | G15: Appliances | H15: 3 | I15: 59.99 | J15: Credit Card | K15: North | L15: Standard | M15: 45351 | N15: 179.97
A16: TRX0191 | B16: 45409 | C16: CUST038 | D16: Michelle Rogers | E16: P002 | F16: Smartphone | G16: Electronics | H16: 3 | I16: 699.99 | J16: Credit Card | K16: West | L16: Basic | M16: 44577 | N16: 2099.97
A17: TRX0230 | B17: 45409 | C17: CUST027 | D17: George Adams | E17: P001 | F17: Laptop | G17: Electronics | H17: 1 | I17: 899.99 | J17: Debit Card | K17: North | L17: Standard | M17: 44920 | N17: 899.99
A18: TRX0049 | B18: 45410 | C18: CUST025 | D18: Mark Carter | E18: P008 | F18: Bookshelf | G18: Furniture | H18: 4 | I18: 149.99 | J18: Debit Card | K18: North | L18: Premium | M18: 45374 | N18: 599.96
A19: TRX0134 | B19: 45410 | C19: CUST010 | D19: Maria Garcia | E19: P002 | F19: Smartphone | G19: Electronics | H19: 2 | I19: 699.99 | J19: Cash | K19: North | L19: Basic | M19: 44781 | N19: 1399.98
A20: TRX0122 | B20: 45410 | C20: CUST025 | D20: Mark Carter | E20: P001 | F20: Laptop | G20: Electronics | H20: 4 | I20: 899.99 | J20: Credit Card | K20: West | L20: Standard | M20: 45327 | N20: 3599.96
A21: TRX0222 | B21: 45410 | C21: CUST048 | D21: Virginia Sanders | E21: P009 | F21: Monitor | G21: Electronics | H21: 3 | I21: 249.99 | J21: Credit Card | K21: North | L21: Premium | M21: 45224 | N21: 749.97
A22: TRX0231 | B22: 45412 | C22: CUST018 | D22: Barbara Young | E22: P002 | F22: Smartphone | G22: Electronics | H22: 5 | I22: 699.99 | J22: Cash | K22: West | L22: Basic | M22: 45167 | N22: 3499.95
... A251: TRX0064 | B251: 45758 | C251: CUST031 | D251: Steven Turner | E251: P010 | F251: Keyboard | G251: Electronics | H251: 3 | I251: 89.99 | J251: Debit Card | K251: North | L251: Premium | M251: 44878 | N251: 269.97

Sheet Task_4_TS
A1: Transaction_ID | B1: Customer_Name | C1: Product_Name | D1: Total_Amount | E1: Entry_Timestamp | F1: Last_Modified | G1: Days_Since_Entry
A2: ='Final Project Dataset'!A2 -> TRX0155 | B2: ='Final Project Dataset'!D2 -> Paul Baker | C2: ='Final Project Dataset'!F2 -> Monitor | D2: ='Final Project Dataset'!N2 -> 749.97 | E2: =NOW() -> 46171.71 | F2: =NOW() -> 46171.71 | G2: =INT(TODAY()-'Final Project Dataset'!B2) -> 778
A3: ='Final Project Dataset'!A3 -> TRX0023 | B3: ='Final Project Dataset'!D3 -> Joseph Jackson | C3: ='Final Project Dataset'!F3 -> Monitor | D3: ='Final Project Dataset'!N3 -> 749.97 | E3: =NOW() -> 46171.71 | F3: =NOW() -> 46171.71 | G3: =INT(TODAY()-'Final Project Dataset'!B3) -> 775
A4: ='Final Project Dataset'!A4 -> TRX0139 | B4: ='Final Project Dataset'!D4 -> Kevin Scott | C4: ='Final Project Dataset'!F4 -> Blender | D4: ='Final Project Dataset'!N4 -> 179.97 | E4: =NOW() -> 46171.71 | F4: =NOW() -> 46171.71 | G4: =INT(TODAY()-'Final Project Dataset'!B4) -> 772
A5: ='Final Project Dataset'!A5 -> TRX0043 | B5: ='Final Project Dataset'!D5 -> Kathleen Bennett | C5: ='Final Project Dataset'!F5 -> Blender | D5: ='Final Project Dataset'!N5 -> 179.97 | E5: =NOW() -> 46171.71 | F5: =NOW() -> 46171.71 | G5: =INT(TODAY()-'Final Project Dataset'!B5) -> 771
A6: ='Final Project Dataset'!A6 -> TRX0212 | B6: ='Final Project Dataset'!D6 -> Michael Brown | C6: ='Final Project Dataset'!F6 -> Bookshelf | D6: ='Final Project Dataset'!N6 -> 749.95 | E6: =NOW() -> 46171.71 | F6: =NOW() -> 46171.71 | G6: =INT(TODAY()-'Final Project Dataset'!B6) -> 771
A7: ='Final Project Dataset'!A7 -> TRX0092 | B7: ='Final Project Dataset'!D7 -> Dorothy Nelson | C7: ='Final Project Dataset'!F7 -> Blender | D7: ='Final Project Dataset'!N7 -> 119.98 | E7: =NOW() -> 46171.71 | F7: =NOW() -> 46171.71 | G7: =INT(TODAY()-'Final Project Dataset'!B7) -> 768
A8: ='Final Project Dataset'!A8 -> TRX0193 | B8: ='Final Project Dataset'!D8 -> Dorothy Nelson | C8: ='Final Project Dataset'!F8 -> Headphones | D8: ='Final Project Dataset'!N8 -> 749.95 | E8: =NOW() -> 46171.71 | F8: =NOW() -> 46171.71 | G8: =INT(TODAY()-'Final Project Dataset'!B8) -> 768
A9: ='Final Project Dataset'!A9 -> TRX0240 | B9: ='Final Project Dataset'!D9 -> Charles Allen | C9: ='Final Project Dataset'!F9 -> Blender | D9: ='Final Project Dataset'!N9 -> 179.97 | E9: =NOW() -> 46171.71 | F9: =NOW() -> 46171.71 | G9: =INT(TODAY()-'Final Project Dataset'!B9) -> 768
A10: ='Final Project Dataset'!A10 -> TRX0135 | B10: ='Final Project Dataset'!D10 -> Robert Thomas | C10: ='Final Project Dataset'!F10 -> Laptop | D10: ='Final Project Dataset'!N10 -> 2699.97 | E10: =NOW() -> 46171.71 | F10: =NOW() -> 46171.71 | G10: =INT(TODAY()-'Final Project Dataset'!B10) -> 766
A11: ='Final Project Dataset'!A11 -> TRX0185 | B11: ='Final Project Dataset'!D11 -> Karen Hill | C11: ='Final Project Dataset'!F11 -> Blender | D11: ='Final Project Dataset'!N11 -> 179.97 | E11: =NOW() -> 46171.71 | F11: =NOW() -> 46171.71 | G11: =INT(TODAY()-'Final Project Dataset'!B11) -> 763

Sheet Task_5_WA
A1: What-If Analysis - Scenario Manager
A3: Unit_Price | B3: =AVERAGE('Final Project Dataset'!I2:I251) -> 296.67
A4: Quantity | B4: =AVERAGE('Final Project Dataset'!H2:H251) -> 3.012
A5: Discount % | B5: 10
A6: Tax % | B6: 18
A7: Total Revenue | B7: =B3*B4*(1-B5/100)*(1+B6/100) -> 948.97138
A10: Goal Seek Analysis
A12: Unit_Price | B12: =B14/B13 -> 400
A13: Quantity | B13: 5
A14: Target Revenue | B14: 2000
A15: Required Revenue | B15: =B12*B13 -> 2000
A19: 5

Sheet Scenario Summary
B2: Scenario Summary
D3: Current Values: | E3: Best Case | F3: Worst Case | G3: Base Case
E4: Created by Mukesh Kote on 26-05-2026 | F4: Created by Mukesh Kote on 26-05-2026 | G4: Created by Mukesh Kote on 26-05-2026
B5: Changing Cells:
C6: $B$5 | D6: 10 | E6: 5 | F6: 30 | G6: 10
C7: $B$6 | D7: 18 | E7: 18 | F7: 28 | G7: 18
B8: Result Cells:
C9: $B$7 | D9: 948.97138 | E9: 1001.692 | F9: 800.63876 | G9: 948.97138
B10: Notes: Current Values column represents values of changing cells at
B11: time Scenario Summary Report was created. Changing cells for each
B12: scenario are highlighted in gray.

Sheet Task_6 LR
A1: SUMMARY OUTPUT
A3: Regression Statistics
A4: Multiple R | B4: 0.45809869
A5: R Square | B5: 0.20985441
A6: Adjusted R Square | B6: 0.20665544
A7: Standard Error | B7: 921.40854
A8: Observations | B8: 249
A10: ANOVA
B11: df | C11: SS | D11: MS | E11: F | F11: Significance F
A12: Regression | B12: 1 | C12: 55694513 | D12: 55694513 | E12: 65.60062 | F12: 2.5391277e-14
A13: Residual | B13: 247 | C13: 2.0970144e+08 | D13: 848993.7
A14: Total | B14: 248 | C14: 2.6539596e+08
B16: Coefficients | C16: Standard Error | D16: t Stat | E16: P-value | F16: Lower 95% | G16: Upper 95% | H16: Lower 95.0% | I16: Upper 95.0%
A17: Intercept | B17: -148.18856 | C17: 143.94399 | D17: -1.0294877 | E17: 0.30425761 | F17: -431.70277 | G17: 135.32564 | H17: -431.70277 | I17: 135.32564
A18: 3 | B18: 353.7886 | C18: 43.680728 | D18: 8.0994209 | E18: 2.5391277e-14 | F18: 267.7544 | G18: 439.82281 | H18: 267.7544 | I18: 439.82281
A22: RESIDUAL OUTPUT
A24: Observation | B24: Predicted 749.97 | C24: Residuals | D24: Standard Residuals
A25: 1 | B25: 913.17725 | C25: -163.20725 | D25: -0.17748619
A26: 2 | B26: 913.17725 | C26: -733.20725 | D26: -0.79735529
A27: 3 | B27: 913.17725 | C27: -733.20725 | D27: -0.79735529
A28: 4 | B28: 1620.7545 | C28: -870.80445 | D28: -0.94699082
A29: 5 | B29: 559.38864 | C29: -439.40864 | D29: -0.47785235
A30: 6 | B30: 1620.7545 | C30: -870.80445 | D30: -0.94699082
A31: 7 | B31: 913.17725 | C31: -733.20725 | D31: -0.79735529
A32: 8 | B32: 913.17725 | C32: 1786.7928 | D32: 1.9431186
A33: 9 | B33: 913.17725 | C33: -733.20725 | D33: -0.79735529
A34: 10 | B34: 205.60004 | C34: -55.61004 | D34: -0.060475343
A35: 11 | B35: 1620.7545 | C35: -870.80445 | D35: -0.94699082
A36: 12 | B36: 913.17725 | C36: -463.20725 | D36: -0.50373308
... A273: 249 | B273: 913.17725 | C273: -643.20725 | D273: -0.69948122

Sheet Task_7_DA
A1: Sales Overview | D1: Region Analysis | G1: Category Analysis | J1: Segment Analysis
A3: Total Transactions | B3: =COUNTA('Final Project Dataset'!A2:A251) -> 250 | D3: North | E3: =SUMIF('Final Project Dataset'!K2:K251,"North",'Final Project Dataset'!N2:N251) -> 50808.31 | G3: Electronics | H3: =SUMIF('Final Project Dataset'!G2:G251,"Electronics",'Final Project Dataset'!N2:N251) -> 171756.05 | J3: Premium | K3: =SUMIF('Final Project Dataset'!L2:L251,"Premium",'Final Project Dataset'!N2:N251) -> 84657.12
A4: Total Revenue | B4: =SUM('Final Project Dataset'!N2:N251) -> 229192.47 | D4: South | E4: =SUMIF('Final Project Dataset'!K2:K251,"South",'Final Project Dataset'!N2:N251) -> 36398.75 | G4: Furniture | H4: =SUMIF('Final Project Dataset'!G2:G251,"Furniture",'Final Project Dataset'!N2:N251) -> 49097.68 | J4: Standard | K4: =SUMIF('Final Project Dataset'!L2:L251,"Standard",'Final Project Dataset'!N2:N251) -> 82357.54
A5: Average Order Value | B5: =AVERAGE('Final Project Dataset'!N2:N251) -> 916.76988 | D5: East | E5: =SUMIF('Final Project Dataset'!K2:K251,"East",'Final Project Dataset'!N2:N251) -> 59288.39 | G5: Appliances | H5: =SUMIF('Final Project Dataset'!G2:G251,"Appliances",'Final Project Dataset'!N2:N251) -> 8338.74 | J5: Basic | K5: =SUMIF('Final Project Dataset'!L2:L251,"Basic",'Final Project Dataset'!N2:N251) -> 62177.81
A6: Max Order Value | B6: =MAX('Final Project Dataset'!N2:N251) -> 4499.95 | D6: West | E6: =SUMIF('Final Project Dataset'!K2:K251,"West",'Final Project Dataset'!N2:N251) -> 41408.68 | G6: Total | H6: =SUM(H3:H5) -> 229192.47 | J6: Total | K6: =SUM(K3:K5) -> 229192.47
A7: Min Order Value | B7: =MIN('Final Project Dataset'!N2:N251) -> 59.99 | D7: Central | E7: =SUMIF('Final Project Dataset'!K2:K251,"Central",'Final Project Dataset'!N2:N251) -> 41288.34
A8: Total Customers | B8: =COUNTA(_xlfn.UNIQUE('Final Project Dataset'!C2:C251)) -> 50 | D8: Total | E8: =SUM(E3:E7) -> 229192.47
A13: Payment Analysis | D13: Product Analysis | G13: Key Insights
A15: Cash | B15: =COUNTIF('Final Project Dataset'!J2:J251,"Cash") -> 76 | D15: Laptop | E15: =SUMIF('Final Project Dataset'!F2:F251,"Laptop",'Final Project Dataset'!N2:N251) -> 67499.25 | G15: Best Selling Category | H15: =INDEX(G3:G5,MATCH(MAX(H3:H5),H3:H5,0)) -> Electronics
A16: Credit Card | B16: =COUNTIF('Final Project Dataset'!J2:J251,"Credit Card") -> 68 | D16: Smartphone | E16: =SUMIF('Final Project Dataset'!F2:F251,"Smartphone",'Final Project Dataset'!N2:N251) -> 67199.04 | G16: Best Region | H16: =INDEX(D3:D7,MATCH(MAX(E3:E7),E3:E7,0)) -> East
A17: Debit Card | B17: =COUNTIF('Final Project Dataset'!J2:J251,"Debit Card") -> 54 | D17: Headphones | E17: =SUMIF('Final Project Dataset'!F2:F251,"Headphones",'Final Project Dataset'!N2:N251) -> 7049.53 | G17: Best Segment | H17: =INDEX(J3:J5,MATCH(MAX(K3:K5),K3:K5,0)) -> Premium
A18: PayPal | B18: =COUNTIF('Final Project Dataset'!J2:J251,"PayPal") -> 52 | D18: Monitor | E18: =SUMIF('Final Project Dataset'!F2:F251,"Monitor",'Final Project Dataset'!N2:N251) -> 21999.12 | G18: Most Used Payment | H18: =INDEX(A15:A18,MATCH(MAX(B15:B18),B15:B18,0)) -> Cash
D19: Keyboard | E19: =SUMIF('Final Project Dataset'!F2:F251,"Keyboard",'Final Project Dataset'!N2:N251) -> 8009.11 | G19: Best Product | H19: =INDEX(D15:D24,MATCH(MAX(E15:E24),E15:E24,0)) -> Laptop
D20: Coffee Maker | E20: =SUMIF('Final Project Dataset'!F2:F251,"Coffee Maker",'Final Project Dataset'!N2:N251) -> 3119.61 | G20: Total Revenue | H20: =B4 -> 229192.47
D21: Blender | E21: =SUMIF('Final Project Dataset'!F2:F251,"Blender",'Final Project Dataset'!N2:N251) -> 5219.13
D22: Office Chair | E22: =SUMIF('Final Project Dataset'!F2:F251,"Office Chair",'Final Project Dataset'!N2:N251) -> 10399.48
D23: Desk | E23: =SUMIF('Final Project Dataset'!F2:F251,"Desk",'Final Project Dataset'!N2:N251) -> 23399.22
D24: Bookshelf | E24: =SUMIF('Final Project Dataset'!F2:F251,"Bookshelf",'Final Project Dataset'!N2:N251) -> 15298.98
D25: Top Product | E25: =INDEX(D15:D24,MATCH(MAX(E15:E24),E15:E24,0)) -> Laptop

Sheet Task_8 HVC
A1: Customer_ID | B1: Customer_Name | C1: Customer_Segment | D1: Total_Purchases | E1: Total_Amount | F1: Avg_Amount | G1: Max_Amount | H1: Min_Amount | I1: Value_Category | K1: GroupBy Summary | N1: Rank | O1: Customer_Name | P1: Total_Amount
A2: {=IFERROR(INDEX('Final Project Dataset'!C$2:C$251,MATCH(0,COUNTIF(A$1:A1,'Final Project Dataset'!C$2:C$251),0)),"")} -> CUST023 | B2: =IF(A2="","",IFERROR(INDEX('Final Project Dataset'!D$2:D$251,MATCH(A2,'Final Project Dataset'!C$2:C$251,0)),"")) -> Paul Baker | C2: =IF(A2="","",IFERROR(INDEX('Final Project Dataset'!L$2:L$251,MATCH(A2,'Final Project Dataset'!C$2:C$251,0)),"")) -> Basic | D2: =IF(A2="","",COUNTIF('Final Project Dataset'!C$2:C$251,A2)) -> 8 | E2: =IF(A2="","",SUMIF('Final Project Dataset'!C$2:C$251,A2,'Final Project Dataset'!N$2:N$251)) -> 8309.74 | F2: =IF(A2="","",AVERAGEIF('Final Project Dataset'!C$2:C$251,A2,'Final Project Dataset'!N$2:N$251)) -> 1038.7175 | G2: =IF(A2="","",_xlfn.MAXIFS('Final Project Dataset'!N$2:N$251,'Final Project Dataset'!C$2:C$251,A2)) -> 4499.95 | H2: =IF(A2="","",_xlfn.MINIFS('Final Project Dataset'!N$2:N$251,'Final Project Dataset'!C$2:C$251,A2)) -> 179.98 | I2: =IF(A2="","",IF(E2>=10000,"1️⃣ High Value",IF(E2>=5000,"2️⃣ Medium Value","3️⃣ Low Value"))) -> 2️⃣ Medium Value | K2: Total Customers | L2: =COUNTA(A2:A51) -> 50 | N2: 1 | O2: =IFERROR(INDEX($B$2:$B$51,MATCH(LARGE($E$2:$E$51,N2),$E$2:$E$51,0)),"") -> Mark Carter | P2: =IFERROR(LARGE($E$2:$E$51,N2),"") -> 15659.65
A3: {=IFERROR(INDEX('Final Project Dataset'!C$2:C$251,MATCH(0,COUNTIF(A$1:A2,'Final Project Dataset'!C$2:C$251),0)),"")} -> CUST013 | B3: =IF(A3="","",IFERROR(INDEX('Final Project Dataset'!D$2:D$251,MATCH(A3,'Final Project Dataset'!C$2:C$251,0)),"")) -> Joseph Jackson | C3: =IF(A3="","",IFERROR(INDEX('Final Project Dataset'!L$2:L$251,MATCH(A3,'Final Project Dataset'!C$2:C$251,0)),"")) -> Premium | D3: =IF(A3="","",COUNTIF('Final Project Dataset'!C$2:C$251,A3)) -> 5 | E3: =IF(A3="","",SUMIF('Final Project Dataset'!C$2:C$251,A3,'Final Project Dataset'!N$2:N$251)) -> 6949.84 | F3: =IF(A3="","",AVERAGEIF('Final Project Dataset'!C$2:C$251,A3,'Final Project Dataset'!N$2:N$251)) -> 1389.968 | G3: =IF(A3="","",_xlfn.MAXIFS('Final Project Dataset'!N$2:N$251,'Final Project Dataset'!C$2:C$251,A3)) -> 4499.95 | H3: =IF(A3="","",_xlfn.MINIFS('Final Project Dataset'!N$2:N$251,'Final Project Dataset'!C$2:C$251,A3)) -> 149.99 | I3: =IF(A3="","",IF(E3>=10000,"1️⃣ High Value",IF(E3>=5000,"2️⃣ Medium Value","3️⃣ Low Value"))) -> 2️⃣ Medium Value | K3: High Value Customers | L3: =COUNTIF(I2:I51,"1️⃣ High Value") -> 3 | N3: 2 | O3: =IFERROR(INDEX($B$2:$B$51,MATCH(LARGE($E$2:$E$51,N3),$E$2:$E$51,0)),"") -> Edward Mitchell | P3: =IFERROR(LARGE($E$2:$E$51,N3),"") -> 11919.77
A4: {=IFERROR(INDEX('Final Project Dataset'!C$2:C$251,MATCH(0,COUNTIF(A$1:A3,'Final Project Dataset'!C$2:C$251),0)),"")} -> CUST021 | B4: =IF(A4="","",IFERROR(INDEX('Final Project Dataset'!D$2:D$251,MATCH(A4,'Final Project Dataset'!C$2:C$251,0)),"")) -> Kevin Scott | C4: =IF(A4="","",IFERROR(INDEX('Final Project Dataset'!L$2:L$251,MATCH(A4,'Final Project Dataset'!C$2:C$251,0)),"")) -> Standard | D4: =IF(A4="","",COUNTIF('Final Project Dataset'!C$2:C$251,A4)) -> 6 | E4: =IF(A4="","",SUMIF('Final Project Dataset'!C$2:C$251,A4,'Final Project Dataset'!N$2:N$251)) -> 3259.87 | F4: =IF(A4="","",AVERAGEIF('Final Project Dataset'!C$2:C$251,A4,'Final Project Dataset'!N$2:N$251)) -> 543.31167 | G4: =IF(A4="","",_xlfn.MAXIFS('Final Project Dataset'!N$2:N$251,'Final Project Dataset'!C$2:C$251,A4)) -> 899.99 | H4: =IF(A4="","",_xlfn.MINIFS('Final Project Dataset'!N$2:N$251,'Final Project Dataset'!C$2:C$251,A4)) -> 79.99 | I4: =IF(A4="","",IF(E4>=10000,"1️⃣ High Value",IF(E4>=5000,"2️⃣ Medium Value","3️⃣ Low Value"))) -> 3️⃣ Low Value | K4: Medium Value Customers | L4: =COUNTIF(I2:I51,"2️⃣ Medium Value") -> 17 | N4: 3 | O4: =IFERROR(INDEX($B$2:$B$51,MATCH(LARGE($E$2:$E$51,N4),$E$2:$E$51,0)),"") -> Barbara Young | P4: =IFERROR(LARGE($E$2:$E$51,N4),"") -> 10649.8
A5: {=IFERROR(INDEX('Final Project Dataset'!C$2:C$251,MATCH(0,COUNTIF(A$1:A4,'Final Project Dataset'!C$2:C$251),0)),"")} -> CUST046 | B5: =IF(A5="","",IFERROR(INDEX('Final Project Dataset'!D$2:D$251,MATCH(A5,'Final Project Dataset'!C$2:C$251,0)),"")) -> Kathleen Bennett | C5: =IF(A5="","",IFERROR(INDEX('Final Project Dataset'!L$2:L$251,MATCH(A5,'Final Project Dataset'!C$2:C$251,0)),"")) -> Premium | D5: =IF(A5="","",COUNTIF('Final Project Dataset'!C$2:C$251,A5)) -> 6 | E5: =IF(A5="","",SUMIF('Final Project Dataset'!C$2:C$251,A5,'Final Project Dataset'!N$2:N$251)) -> 4309.81 | F5: =IF(A5="","",AVERAGEIF('Final Project Dataset'!C$2:C$251,A5,'Final Project Dataset'!N$2:N$251)) -> 718.30167 | G5: =IF(A5="","",_xlfn.MAXIFS('Final Project Dataset'!N$2:N$251,'Final Project Dataset'!C$2:C$251,A5)) -> 2099.97 | H5: =IF(A5="","",_xlfn.MINIFS('Final Project Dataset'!N$2:N$251,'Final Project Dataset'!C$2:C$251,A5)) -> 179.97 | I5: =IF(A5="","",IF(E5>=10000,"1️⃣ High Value",IF(E5>=5000,"2️⃣ Medium Value","3️⃣ Low Value"))) -> 3️⃣ Low Value | K5: Low Value Customers | L5: =COUNTIF(I2:I51,"3️⃣ Low Value") -> 30 | N5: 4 | O5: =IFERROR(INDEX($B$2:$B$51,MATCH(LARGE($E$2:$E$51,N5),$E$2:$E$51,0)),"") -> Patricia Moore | P5: =IFERROR(LARGE($E$2:$E$51,N5),"") -> 9799.73
A6: {=IFERROR(INDEX('Final Project Dataset'!C$2:C$251,MATCH(0,COUNTIF(A$1:A5,'Final Project Dataset'!C$2:C$251),0)),"")} -> CUST003 | B6: =IF(A6="","",IFERROR(INDEX('Final Project Dataset'!D$2:D$251,MATCH(A6,'Final Project Dataset'!C$2:C$251,0)),"")) -> Michael Brown | C6: =IF(A6="","",IFERROR(INDEX('Final Project Dataset'!L$2:L$251,MATCH(A6,'Final Project Dataset'!C$2:C$251,0)),"")) -> Premium | D6: =IF(A6="","",COUNTIF('Final Project Dataset'!C$2:C$251,A6)) -> 9 | E6: =IF(A6="","",SUMIF('Final Project Dataset'!C$2:C$251,A6,'Final Project Dataset'!N$2:N$251)) -> 6169.74 | F6: =IF(A6="","",AVERAGEIF('Final Project Dataset'!C$2:C$251,A6,'Final Project Dataset'!N$2:N$251)) -> 685.52667 | G6: =IF(A6="","",_xlfn.MAXIFS('Final Project Dataset'!N$2:N$251,'Final Project Dataset'!C$2:C$251,A6)) -> 1399.98 | H6: =IF(A6="","",_xlfn.MINIFS('Final Project Dataset'!N$2:N$251,'Final Project Dataset'!C$2:C$251,A6)) -> 269.97 | I6: =IF(A6="","",IF(E6>=10000,"1️⃣ High Value",IF(E6>=5000,"2️⃣ Medium Value","3️⃣ Low Value"))) -> 2️⃣ Medium Value | K6: Total Revenue | L6: =SUM(E2:E51) -> 229192.47 | N6: 5 | O6: =IFERROR(INDEX($B$2:$B$51,MATCH(LARGE($E$2:$E$51,N6),$E$2:$E$51,0)),"") -> Paul Baker | P6: =IFERROR(LARGE($E$2:$E$51,N6),"") -> 8309.74
A7: {=IFERROR(INDEX('Final Project Dataset'!C$2:C$251,MATCH(0,COUNTIF(A$1:A6,'Final Project Dataset'!C$2:C$251),0)),"")} -> CUST024 | B7: =IF(A7="","",IFERROR(INDEX('Final Project Dataset'!D$2:D$251,MATCH(A7,'Final Project Dataset'!C$2:C$251,0)),"")) -> Dorothy Nelson | C7: =IF(A7="","",IFERROR(INDEX('Final Project Dataset'!L$2:L$251,MATCH(A7,'Final Project Dataset'!C$2:C$251,0)),"")) -> Standard | D7: =IF(A7="","",COUNTIF('Final Project Dataset'!C$2:C$251,A7)) -> 6 | E7: =IF(A7="","",SUMIF('Final Project Dataset'!C$2:C$251,A7,'Final Project Dataset'!N$2:N$251)) -> 8269.79 | F7: =IF(A7="","",AVERAGEIF('Final Project Dataset'!C$2:C$251,A7,'Final Project Dataset'!N$2:N$251)) -> 1378.2983 | G7: =IF(A7="","",_xlfn.MAXIFS('Final Project Dataset'!N$2:N$251,'Final Project Dataset'!C$2:C$251,A7)) -> 2799.96 | H7: =IF(A7="","",_xlfn.MINIFS('Final Project Dataset'!N$2:N$251,'Final Project Dataset'!C$2:C$251,A7)) -> 119.98 | I7: =IF(A7="","",IF(E7>=10000,"1️⃣ High Value",IF(E7>=5000,"2️⃣ Medium Value","3️⃣ Low Value"))) -> 2️⃣ Medium Value | K7: Avg Revenue per Customer | L7: =AVERAGE(E2:E51) -> 4583.8494 | N7: 6 | O7: =IFERROR(INDEX($B$2:$B$51,MATCH(LARGE($E$2:$E$51,N7),$E$2:$E$51,0)),"") -> Dorothy Nelson | P7: =IFERROR(LARGE($E$2:$E$51,N7),"") -> 8269.79
A8: {=IFERROR(INDEX('Final Project Dataset'!C$2:C$251,MATCH(0,COUNTIF(A$1:A7,'Final Project Dataset'!C$2:C$251),0)),"")} -> CUST017 | B8: =IF(A8="","",IFERROR(INDEX('Final Project Dataset'!D$2:D$251,MATCH(A8,'Final Project Dataset'!C$2:C$251,0)),"")) -> Charles Allen | C8: =IF(A8="","",IFERROR(INDEX('Final Project Dataset'!L$2:L$251,MATCH(A8,'Final Project Dataset'!C$2:C$251,0)),"")) -> Basic | D8: =IF(A8="","",COUNTIF('Final Project Dataset'!C$2:C$251,A8)) -> 9 | E8: =IF(A8="","",SUMIF('Final Project Dataset'!C$2:C$251,A8,'Final Project Dataset'!N$2:N$251)) -> 5089.73 | F8: =IF(A8="","",AVERAGEIF('Final Project Dataset'!C$2:C$251,A8,'Final Project Dataset'!N$2:N$251)) -> 565.52556 | G8: =IF(A8="","",_xlfn.MAXIFS('Final Project Dataset'!N$2:N$251,'Final Project Dataset'!C$2:C$251,A8)) -> 1499.95 | H8: =IF(A8="","",_xlfn.MINIFS('Final Project Dataset'!N$2:N$251,'Final Project Dataset'!C$2:C$251,A8)) -> 79.99 | I8: =IF(A8="","",IF(E8>=10000,"1️⃣ High Value",IF(E8>=5000,"2️⃣ Medium Value","3️⃣ Low Value"))) -> 2️⃣ Medium Value | K8: Top Customer | L8: =INDEX(B2:B51,MATCH(MAX(E2:E51),E2:E51,0)) -> Mark Carter | N8: 7 | O8: =IFERROR(INDEX($B$2:$B$51,MATCH(LARGE($E$2:$E$51,N8),$E$2:$E$51,0)),"") -> Karen Hill | P8: =IFERROR(LARGE($E$2:$E$51,N8),"") -> 8009.77
A9: {=IFERROR(INDEX('Final Project Dataset'!C$2:C$251,MATCH(0,COUNTIF(A$1:A8,'Final Project Dataset'!C$2:C$251),0)),"")} -> CUST009 | B9: =IF(A9="","",IFERROR(INDEX('Final Project Dataset'!D$2:D$251,MATCH(A9,'Final Project Dataset'!C$2:C$251,0)),"")) -> Robert Thomas | C9: =IF(A9="","",IFERROR(INDEX('Final Project Dataset'!L$2:L$251,MATCH(A9,'Final Project Dataset'!C$2:C$251,0)),"")) -> Standard | D9: =IF(A9="","",COUNTIF('Final Project Dataset'!C$2:C$251,A9)) -> 5 | E9: =IF(A9="","",SUMIF('Final Project Dataset'!C$2:C$251,A9,'Final Project Dataset'!N$2:N$251)) -> 3509.9 | F9: =IF(A9="","",AVERAGEIF('Final Project Dataset'!C$2:C$251,A9,'Final Project Dataset'!N$2:N$251)) -> 701.98 | G9: =IF(A9="","",_xlfn.MAXIFS('Final Project Dataset'!N$2:N$251,'Final Project Dataset'!C$2:C$251,A9)) -> 2699.97 | H9: =IF(A9="","",_xlfn.MINIFS('Final Project Dataset'!N$2:N$251,'Final Project Dataset'!C$2:C$251,A9)) -> 89.99 | I9: =IF(A9="","",IF(E9>=10000,"1️⃣ High Value",IF(E9>=5000,"2️⃣ Medium Value","3️⃣ Low Value"))) -> 3️⃣ Low Value | K9: Top Customer Amount | L9: =MAX(E2:E51) -> 15659.65 | N9: 8 | O9: =IFERROR(INDEX($B$2:$B$51,MATCH(LARGE($E$2:$E$51,N9),$E$2:$E$51,0)),"") -> Daniel King | P9: =IFERROR(LARGE($E$2:$E$51,N9),"") -> 7309.8
A10: {=IFERROR(INDEX('Final Project Dataset'!C$2:C$251,MATCH(0,COUNTIF(A$1:A9,'Final Project Dataset'!C$2:C$251),0)),"")} -> CUST026 | B10: =IF(A10="","",IFERROR(INDEX('Final Project Dataset'!D$2:D$251,MATCH(A10,'Final Project Dataset'!C$2:C$251,0)),"")) -> Karen Hill | C10: =IF(A10="","",IFERROR(INDEX('Final Project Dataset'!L$2:L$251,MATCH(A10,'Final Project Dataset'!C$2:C$251,0)),"")) -> Premium | D10: =IF(A10="","",COUNTIF('Final Project Dataset'!C$2:C$251,A10)) -> 8 | E10: =IF(A10="","",SUMIF('Final Project Dataset'!C$2:C$251,A10,'Final Project Dataset'!N$2:N$251)) -> 8009.77 | F10: =IF(A10="","",AVERAGEIF('Final Project Dataset'!C$2:C$251,A10,'Final Project Dataset'!N$2:N$251)) -> 1001.2212 | G10: =IF(A10="","",_xlfn.MAXIFS('Final Project Dataset'!N$2:N$251,'Final Project Dataset'!C$2:C$251,A10)) -> 2799.96 | H10: =IF(A10="","",_xlfn.MINIFS('Final Project Dataset'!N$2:N$251,'Final Project Dataset'!C$2:C$251,A10)) -> 179.97 | I10: =IF(A10="","",IF(E10>=10000,"1️⃣ High Value",IF(E10>=5000,"2️⃣ Medium Value","3️⃣ Low Value"))) -> 2️⃣ Medium Value | K10: Lowest Customer | L10: =INDEX(B2:B51,MATCH(MIN(E2:E51),E2:E51,0)) -> James Johnson | N10: 9 | O10: =IFERROR(INDEX($B$2:$B$51,MATCH(LARGE($E$2:$E$51,N10),$E$2:$E$51,0)),"") -> Lawrence Reed | P10: =IFERROR(LARGE($E$2:$E$51,N10),"") -> 6989.77
A11: {=IFERROR(INDEX('Final Project Dataset'!C$2:C$251,MATCH(0,COUNTIF(A$1:A10,'Final Project Dataset'!C$2:C$251),0)),"")} -> CUST022 | B11: =IF(A11="","",IFERROR(INDEX('Final Project Dataset'!D$2:D$251,MATCH(A11,'Final Project Dataset'!C$2:C$251,0)),"")) -> Susan Green | C11: =IF(A11="","",IFERROR(INDEX('Final Project Dataset'!L$2:L$251,MATCH(A11,'Final Project Dataset'!C$2:C$251,0)),"")) -> Standard | D11: =IF(A11="","",COUNTIF('Final Project Dataset'!C$2:C$251,A11)) -> 4 | E11: =IF(A11="","",SUMIF('Final Project Dataset'!C$2:C$251,A11,'Final Project Dataset'!N$2:N$251)) -> 1979.89 | F11: =IF(A11="","",AVERAGEIF('Final Project Dataset'!C$2:C$251,A11,'Final Project Dataset'!N$2:N$251)) -> 494.9725 | G11: =IF(A11="","",_xlfn.MAXIFS('Final Project Dataset'!N$2:N$251,'Final Project Dataset'!C$2:C$251,A11)) -> 1499.95 | H11: =IF(A11="","",_xlfn.MINIFS('Final Project Dataset'!N$2:N$251,'Final Project Dataset'!C$2:C$251,A11)) -> 89.99 | I11: =IF(A11="","",IF(E11>=10000,"1️⃣ High Value",IF(E11>=5000,"2️⃣ Medium Value","3️⃣ Low Value"))) -> 3️⃣ Low Value | K11: Lowest Customer Amount | L11: =MIN(E2:E51) -> 179.97 | N11: 10 | O11: =IFERROR(INDEX($B$2:$B$51,MATCH(LARGE($E$2:$E$51,N11),$E$2:$E$51,0)),"") -> Joseph Jackson | P11: =IFERROR(LARGE($E$2:$E$51,N11),"") -> 6949.84
A12: {=IFERROR(INDEX('Final Project Dataset'!C$2:C$251,MATCH(0,COUNTIF(A$1:A11,'Final Project Dataset'!C$2:C$251),0)),"")} -> CUST041 | B12: =IF(A12="","",IFERROR(INDEX('Final Project Dataset'!D$2:D$251,MATCH(A12,'Final Project Dataset'!C$2:C$251,0)),"")) -> Peter Richardson | C12: =IF(A12="","",IFERROR(INDEX('Final Project Dataset'!L$2:L$251,MATCH(A12,'Final Project Dataset'!C$2:C$251,0)),"")) -> Premium | D12: =IF(A12="","",COUNTIF('Final Project Dataset'!C$2:C$251,A12)) -> 5 | E12: =IF(A12="","",SUMIF('Final Project Dataset'!C$2:C$251,A12,'Final Project Dataset'!N$2:N$251)) -> 5949.85 | F12: =IF(A12="","",AVERAGEIF('Final Project Dataset'!C$2:C$251,A12,'Final Project Dataset'!N$2:N$251)) -> 1189.97 | G12: =IF(A12="","",_xlfn.MAXIFS('Final Project Dataset'!N$2:N$251,'Final Project Dataset'!C$2:C$251,A12)) -> 2799.96 | H12: =IF(A12="","",_xlfn.MINIFS('Final Project Dataset'!N$2:N$251,'Final Project Dataset'!C$2:C$251,A12)) -> 449.97 | I12: =IF(A12="","",IF(E12>=10000,"1️⃣ High Value",IF(E12>=5000,"2️⃣ Medium Value","3️⃣ Low Value"))) -> 2️⃣ Medium Value
A13: {=IFERROR(INDEX('Final Project Dataset'!C$2:C$251,MATCH(0,COUNTIF(A$1:A12,'Final Project Dataset'!C$2:C$251),0)),"")} -> CUST043 | B13: =IF(A13="","",IFERROR(INDEX('Final Project Dataset'!D$2:D$251,MATCH(A13,'Final Project Dataset'!C$2:C$251,0)),"")) -> Dennis Gray | C13: =IF(A13="","",IFERROR(INDEX('Final Project Dataset'!L$2:L$251,MATCH(A13,'Final Project Dataset'!C$2:C$251,0)),"")) -> Standard | D13: =IF(A13="","",COUNTIF('Final Project Dataset'!C$2:C$251,A13)) -> 2 | E13: =IF(A13="","",SUMIF('Final Project Dataset'!C$2:C$251,A13,'Final Project Dataset'!N$2:N$251)) -> 479.92 | F13: =IF(A13="","",AVERAGEIF('Final Project Dataset'!C$2:C$251,A13,'Final Project Dataset'!N$2:N$251)) -> 239.96 | G13: =IF(A13="","",_xlfn.MAXIFS('Final Project Dataset'!N$2:N$251,'Final Project Dataset'!C$2:C$251,A13)) -> 299.95 | H13: =IF(A13="","",_xlfn.MINIFS('Final Project Dataset'!N$2:N$251,'Final Project Dataset'!C$2:C$251,A13)) -> 179.97 | I13: =IF(A13="","",IF(E13>=10000,"1️⃣ High Value",IF(E13>=5000,"2️⃣ Medium Value","3️⃣ Low Value"))) -> 3️⃣ Low Value
A14: {=IFERROR(INDEX('Final Project Dataset'!C$2:C$251,MATCH(0,COUNTIF(A$1:A13,'Final Project Dataset'!C$2:C$251),0)),"")} -> CUST038 | B14: =IF(A14="","",IFERROR(INDEX('Final Project Dataset'!D$2:D$251,MATCH(A14,'Final Project Dataset'!C$2:C$251,0)),"")) -> Michelle Rogers | C14: =IF(A14="","",IFERROR(INDEX('Final Project Dataset'!L$2:L$251,MATCH(A14,'Final Project Dataset'!C$2:C$251,0)),"")) -> Basic | D14: =IF(A14="","",COUNTIF('Final Project Dataset'!C$2:C$251,A14)) -> 2 | E14: =IF(A14="","",SUMIF('Final Project Dataset'!C$2:C$251,A14,'Final Project Dataset'!N$2:N$251)) -> 4199.94 | F14: =IF(A14="","",AVERAGEIF('Final Project Dataset'!C$2:C$251,A14,'Final Project Dataset'!N$2:N$251)) -> 2099.97 | G14: =IF(A14="","",_xlfn.MAXIFS('Final Project Dataset'!N$2:N$251,'Final Project Dataset'!C$2:C$251,A14)) -> 2099.97 | H14: =IF(A14="","",_xlfn.MINIFS('Final Project Dataset'!N$2:N$251,'Final Project Dataset'!C$2:C$251,A14)) -> 2099.97 | I14: =IF(A14="","",IF(E14>=10000,"1️⃣ High Value",IF(E14>=5000,"2️⃣ Medium Value","3️⃣ Low Value"))) -> 3️⃣ Low Value
A15: {=IFERROR(INDEX('Final Project Dataset'!C$2:C$251,MATCH(0,COUNTIF(A$1:A14,'Final Project Dataset'!C$2:C$251),0)),"")} -> CUST027 | B15: =IF(A15="","",IFERROR(INDEX('Final Project Dataset'!D$2:D$251,MATCH(A15,'Final Project Dataset'!C$2:C$251,0)),"")) -> George Adams | C15: =IF(A15="","",IFERROR(INDEX('Final Project Dataset'!L$2:L$251,MATCH(A15,'Final Project Dataset'!C$2:C$251,0)),"")) -> Standard | D15: =IF(A15="","",COUNTIF('Final Project Dataset'!C$2:C$251,A15)) -> 3 | E15: =IF(A15="","",SUMIF('Final Project Dataset'!C$2:C$251,A15,'Final Project Dataset'!N$2:N$251)) -> 3779.93 | F15: =IF(A15="","",AVERAGEIF('Final Project Dataset'!C$2:C$251,A15,'Final Project Dataset'!N$2:N$251)) -> 1259.9767 | G15: =IF(A15="","",_xlfn.MAXIFS('Final Project Dataset'!N$2:N$251,'Final Project Dataset'!C$2:C$251,A15)) -> 2699.97 | H15: =IF(A15="","",_xlfn.MINIFS('Final Project Dataset'!N$2:N$251,'Final Project Dataset'!C$2:C$251,A15)) -> 179.97 | I15: =IF(A15="","",IF(E15>=10000,"1️⃣ High Value",IF(E15>=5000,"2️⃣ Medium Value","3️⃣ Low Value"))) -> 3️⃣ Low Value
A16: {=IFERROR(INDEX('Final Project Dataset'!C$2:C$251,MATCH(0,COUNTIF(A$1:A15,'Final Project Dataset'!C$2:C$251),0)),"")} -> CUST025 | B16: =IF(A16="","",IFERROR(INDEX('Final Project Dataset'!D$2:D$251,MATCH(A16,'Final Project Dataset'!C$2:C$251,0)),"")) -> Mark Carter | C16: =IF(A16="","",IFERROR(INDEX('Final Project Dataset'!L$2:L$251,MATCH(A16,'Final Project Dataset'!C$2:C$251,0)),"")) -> Premium | D16: =IF(A16="","",COUNTIF('Final Project Dataset'!C$2:C$251,A16)) -> 12 | E16: =IF(A16="","",SUMIF('Final Project Dataset'!C$2:C$251,A16,'Final Project Dataset'!N$2:N$251)) -> 15659.65 | F16: =IF(A16="","",AVERAGEIF('Final Project Dataset'!C$2:C$251,A16,'Final Project Dataset'!N$2:N$251)) -> 1304.9708 | G16: =IF(A16="","",_xlfn.MAXIFS('Final Project Dataset'!N$2:N$251,'Final Project Dataset'!C$2:C$251,A16)) -> 3599.96 | H16: =IF(A16="","",_xlfn.MINIFS('Final Project Dataset'!N$2:N$251,'Final Project Dataset'!C$2:C$251,A16)) -> 179.98 | I16: =IF(A16="","",IF(E16>=10000,"1️⃣ High Value",IF(E16>=5000,"2️⃣ Medium Value","3️⃣ Low Value"))) -> 1️⃣ High Value
A17: {=IFERROR(INDEX('Final Project Dataset'!C$2:C$251,MATCH(0,COUNTIF(A$1:A16,'Final Project Dataset'!C$2:C$251),0)),"")} -> CUST010 | B17: =IF(A17="","",IFERROR(INDEX('Final Project Dataset'!D$2:D$251,MATCH(A17,'Final Project Dataset'!C$2:C$251,0)),"")) -> Maria Garcia | C17: =IF(A17="","",IFERROR(INDEX('Final Project Dataset'!L$2:L$251,MATCH(A17,'Final Project Dataset'!C$2:C$251,0)),"")) -> Basic | D17: =IF(A17="","",COUNTIF('Final Project Dataset'!C$2:C$251,A17)) -> 4 | E17: =IF(A17="","",SUMIF('Final Project Dataset'!C$2:C$251,A17,'Final Project Dataset'!N$2:N$251)) -> 1909.93 | F17: =IF(A17="","",AVERAGEIF('Final Project Dataset'!C$2:C$251,A17,'Final Project Dataset'!N$2:N$251)) -> 477.4825 | G17: =IF(A17="","",_xlfn.MAXIFS('Final Project Dataset'!N$2:N$251,'Final Project Dataset'!C$2:C$251,A17)) -> 1399.98 | H17: =IF(A17="","",_xlfn.MINIFS('Final Project Dataset'!N$2:N$251,'Final Project Dataset'!C$2:C$251,A17)) -> 89.99 | I17: =IF(A17="","",IF(E17>=10000,"1️⃣ High Value",IF(E17>=5000,"2️⃣ Medium Value","3️⃣ Low Value"))) -> 3️⃣ Low Value
A18: {=IFERROR(INDEX('Final Project Dataset'!C$2:C$251,MATCH(0,COUNTIF(A$1:A17,'Final Project Dataset'!C$2:C$251),0)),"")} -> CUST048 | B18: =IF(A18="","",IFERROR(INDEX('Final Project Dataset'!D$2:D$251,MATCH(A18,'Final Project Dataset'!C$2:C$251,0)),"")) -> Virginia Sanders | C18: =IF(A18="","",IFERROR(INDEX('Final Project Dataset'!L$2:L$251,MATCH(A18,'Final Project Dataset'!C$2:C$251,0)),"")) -> Premium | D18: =IF(A18="","",COUNTIF('Final Project Dataset'!C$2:C$251,A18)) -> 6 | E18: =IF(A18="","",SUMIF('Final Project Dataset'!C$2:C$251,A18,'Final Project Dataset'!N$2:N$251)) -> 4789.79 | F18: =IF(A18="","",AVERAGEIF('Final Project Dataset'!C$2:C$251,A18,'Final Project Dataset'!N$2:N$251)) -> 798.29833 | G18: =IF(A18="","",_xlfn.MAXIFS('Final Project Dataset'!N$2:N$251,'Final Project Dataset'!C$2:C$251,A18)) -> 1499.95 | H18: =IF(A18="","",_xlfn.MINIFS('Final Project Dataset'!N$2:N$251,'Final Project Dataset'!C$2:C$251,A18)) -> 239.97 | I18: =IF(A18="","",IF(E18>=10000,"1️⃣ High Value",IF(E18>=5000,"2️⃣ Medium Value","3️⃣ Low Value"))) -> 3️⃣ Low Value
A19: {=IFERROR(INDEX('Final Project Dataset'!C$2:C$251,MATCH(0,COUNTIF(A$1:A18,'Final Project Dataset'!C$2:C$251),0)),"")} -> CUST018 | B19: =IF(A19="","",IFERROR(INDEX('Final Project Dataset'!D$2:D$251,MATCH(A19,'Final Project Dataset'!C$2:C$251,0)),"")) -> Barbara Young | C19: =IF(A19="","",IFERROR(INDEX('Final Project Dataset'!L$2:L$251,MATCH(A19,'Final Project Dataset'!C$2:C$251,0)),"")) -> Basic | D19: =IF(A19="","",COUNTIF('Final Project Dataset'!C$2:C$251,A19)) -> 5 | E19: =IF(A19="","",SUMIF('Final Project Dataset'!C$2:C$251,A19,'Final Project Dataset'!N$2:N$251)) -> 10649.8 | F19: =IF(A19="","",AVERAGEIF('Final Project Dataset'!C$2:C$251,A19,'Final Project Dataset'!N$2:N$251)) -> 2129.96 | G19: =IF(A19="","",_xlfn.MAXIFS('Final Project Dataset'!N$2:N$251,'Final Project Dataset'!C$2:C$251,A19)) -> 3499.95 | H19: =IF(A19="","",_xlfn.MINIFS('Final Project Dataset'!N$2:N$251,'Final Project Dataset'!C$2:C$251,A19)) -> 449.95 | I19: =IF(A19="","",IF(E19>=10000,"1️⃣ High Value",IF(E19>=5000,"2️⃣ Medium Value","3️⃣ Low Value"))) -> 1️⃣ High Value
A20: {=IFERROR(INDEX('Final Project Dataset'!C$2:C$251,MATCH(0,COUNTIF(A$1:A19,'Final Project Dataset'!C$2:C$251),0)),"")} -> CUST012 | B20: =IF(A20="","",IFERROR(INDEX('Final Project Dataset'!D$2:D$251,MATCH(A20,'Final Project Dataset'!C$2:C$251,0)),"")) -> Patricia Moore | C20: =IF(A20="","",IFERROR(INDEX('Final Project Dataset'!L$2:L$251,MATCH(A20,'Final Project Dataset'!C$2:C$251,0)),"")) -> Standard | D20: =IF(A20="","",COUNTIF('Final Project Dataset'!C$2:C$251,A20)) -> 8 | E20: =IF(A20="","",SUMIF('Final Project Dataset'!C$2:C$251,A20,'Final Project Dataset'!N$2:N$251)) -> 9799.73 | F20: =IF(A20="","",AVERAGEIF('Final Project Dataset'!C$2:C$251,A20,'Final Project Dataset'!N$2:N$251)) -> 1224.9662 | G20: =IF(A20="","",_xlfn.MAXIFS('Final Project Dataset'!N$2:N$251,'Final Project Dataset'!C$2:C$251,A20)) -> 3599.96 | H20: =IF(A20="","",_xlfn.MINIFS('Final Project Dataset'!N$2:N$251,'Final Project Dataset'!C$2:C$251,A20)) -> 179.98 | I20: =IF(A20="","",IF(E20>=10000,"1️⃣ High Value",IF(E20>=5000,"2️⃣ Medium Value","3️⃣ Low Value"))) -> 2️⃣ Medium Value
A21: {=IFERROR(INDEX('Final Project Dataset'!C$2:C$251,MATCH(0,COUNTIF(A$1:A20,'Final Project Dataset'!C$2:C$251),0)),"")} -> CUST044 | B21: =IF(A21="","",IFERROR(INDEX('Final Project Dataset'!D$2:D$251,MATCH(A21,'Final Project Dataset'!C$2:C$251,0)),"")) -> Cynthia Price | C21: =IF(A21="","",IFERROR(INDEX('Final Project Dataset'!L$2:L$251,MATCH(A21,'Final Project Dataset'!C$2:C$251,0)),"")) -> Standard | D21: =IF(A21="","",COUNTIF('Final Project Dataset'!C$2:C$251,A21)) -> 5 | E21: =IF(A21="","",SUMIF('Final Project Dataset'!C$2:C$251,A21,'Final Project Dataset'!N$2:N$251)) -> 3769.83 | F21: =IF(A21="","",AVERAGEIF('Final Project Dataset'!C$2:C$251,A21,'Final Project Dataset'!N$2:N$251)) -> 753.966 | G21: =IF(A21="","",_xlfn.MAXIFS('Final Project Dataset'!N$2:N$251,'Final Project Dataset'!C$2:C$251,A21)) -> 1399.98 | H21: =IF(A21="","",_xlfn.MINIFS('Final Project Dataset'!N$2:N$251,'Final Project Dataset'!C$2:C$251,A21)) -> 299.98 | I21: =IF(A21="","",IF(E21>=10000,"1️⃣ High Value",IF(E21>=5000,"2️⃣ Medium Value","3️⃣ Low Value"))) -> 3️⃣ Low Value
A22: {=IFERROR(INDEX('Final Project Dataset'!C$2:C$251,MATCH(0,COUNTIF(A$1:A21,'Final Project Dataset'!C$2:C$251),0)),"")} -> CUST036 | B22: =IF(A22="","",IFERROR(INDEX('Final Project Dataset'!D$2:D$251,MATCH(A22,'Final Project Dataset'!C$2:C$251,0)),"")) -> Nancy Collins | C22: =IF(A22="","",IFERROR(INDEX('Final Project Dataset'!L$2:L$251,MATCH(A22,'Final Project Dataset'!C$2:C$251,0)),"")) -> Standard | D22: =IF(A22="","",COUNTIF('Final Project Dataset'!C$2:C$251,A22)) -> 6 | E22: =IF(A22="","",SUMIF('Final Project Dataset'!C$2:C$251,A22,'Final Project Dataset'!N$2:N$251)) -> 4189.77 | F22: =IF(A22="","",AVERAGEIF('Final Project Dataset'!C$2:C$251,A22,'Final Project Dataset'!N$2:N$251)) -> 698.295 | G22: =IF(A22="","",_xlfn.MAXIFS('Final Project Dataset'!N$2:N$251,'Final Project Dataset'!C$2:C$251,A22)) -> 1249.95 | H22: =IF(A22="","",_xlfn.MINIFS('Final Project Dataset'!N$2:N$251,'Final Project Dataset'!C$2:C$251,A22)) -> 239.97 | I22: =IF(A22="","",IF(E22>=10000,"1️⃣ High Value",IF(E22>=5000,"2️⃣ Medium Value","3️⃣ Low Value"))) -> 3️⃣ Low Value
A23: {=IFERROR(INDEX('Final Project Dataset'!C$2:C$251,MATCH(0,COUNTIF(A$1:A22,'Final Project Dataset'!C$2:C$251),0)),"")} -> CUST014 | B23: =IF(A23="","",IFERROR(INDEX('Final Project Dataset'!D$2:D$251,MATCH(A23,'Final Project Dataset'!C$2:C$251,0)),"")) -> Linda Martin | C23: =IF(A23="","",IFERROR(INDEX('Final Project Dataset'!L$2:L$251,MATCH(A23,'Final Project Dataset'!C$2:C$251,0)),"")) -> Premium | D23: =IF(A23="","",COUNTIF('Final Project Dataset'!C$2:C$251,A23)) -> 4 | E23: =IF(A23="","",SUMIF('Final Project Dataset'!C$2:C$251,A23,'Final Project Dataset'!N$2:N$251)) -> 1289.9 | F23: =IF(A23="","",AVERAGEIF('Final Project Dataset'!C$2:C$251,A23,'Final Project Dataset'!N$2:N$251)) -> 322.475 | G23: =IF(A23="","",_xlfn.MAXIFS('Final Project Dataset'!N$2:N$251,'Final Project Dataset'!C$2:C$251,A23)) -> 449.97 | H23: =IF(A23="","",_xlfn.MINIFS('Final Project Dataset'!N$2:N$251,'Final Project Dataset'!C$2:C$251,A23)) -> 239.97 | I23: =IF(A23="","",IF(E23>=10000,"1️⃣ High Value",IF(E23>=5000,"2️⃣ Medium Value","3️⃣ Low Value"))) -> 3️⃣ Low Value
... A51: {=IFERROR(INDEX('Final Project Dataset'!C$2:C$251,MATCH(0,COUNTIF(A$1:A50,'Final Project Dataset'!C$2:C$251),0)),"")} -> CUST001 | B51: =IF(A51="","",IFERROR(INDEX('Final Project Dataset'!D$2:D$251,MATCH(A51,'Final Project Dataset'!C$2:C$251,0)),"")) -> John Smith | C51: =IF(A51="","",IFERROR(INDEX('Final Project Dataset'!L$2:L$251,MATCH(A51,'Final Project Dataset'!C$2:C$251,0)),"")) -> Standard | D51: =IF(A51="","",COUNTIF('Final Project Dataset'!C$2:C$251,A51)) -> 1 | E51: =IF(A51="","",SUMIF('Final Project Dataset'!C$2:C$251,A51,'Final Project Dataset'!N$2:N$251)) -> 599.96 | F51: =IF(A51="","",AVERAGEIF('Final Project Dataset'!C$2:C$251,A51,'Final Project Dataset'!N$2:N$251)) -> 599.96 | G51: =IF(A51="","",_xlfn.MAXIFS('Final Project Dataset'!N$2:N$251,'Final Project Dataset'!C$2:C$251,A51)) -> 599.96 | H51: =IF(A51="","",_xlfn.MINIFS('Final Project Dataset'!N$2:N$251,'Final Project Dataset'!C$2:C$251,A51)) -> 599.96 | I51: =IF(A51="","",IF(E51>=10000,"1️⃣ High Value",IF(E51>=5000,"2️⃣ Medium Value","3️⃣ Low Value"))) -> 3️⃣ Low Value

Sheet Task_9FP
A1: Product_Name | B1: Count | C1: Total_Amount | D1: Avg_Amount | E1: Rank | G1: Key Results
A2: Laptop | B2: =COUNTIF('Final Project Dataset'!F2:F251,A2) -> 24 | C2: =SUMIF('Final Project Dataset'!F2:F251,A2,'Final Project Dataset'!N2:N251) -> 67499.25 | D2: =AVERAGEIF('Final Project Dataset'!F2:F251,A2,'Final Project Dataset'!N2:N251) -> 2812.4688 | E2: =RANK(B2,$B$2:$B$11,0) -> 6 | G2: Most Purchased Product | H2: =INDEX(A2:A11,MATCH(MAX(B2:B11),B2:B11,0)) -> Keyboard
A3: Smartphone | B3: =COUNTIF('Final Project Dataset'!F3:F252,A3) -> 31 | C3: =SUMIF('Final Project Dataset'!F3:F252,A3,'Final Project Dataset'!N3:N252) -> 67199.04 | D3: =AVERAGEIF('Final Project Dataset'!F3:F252,A3,'Final Project Dataset'!N3:N252) -> 2167.711 | E3: =RANK(B3,$B$2:$B$11,0) -> 3 | G3: Most Purchased Count | H3: =MAX(B2:B11) -> 34
A4: Headphones | B4: =COUNTIF('Final Project Dataset'!F4:F253,A4) -> 16 | C4: =SUMIF('Final Project Dataset'!F4:F253,A4,'Final Project Dataset'!N4:N253) -> 7049.53 | D4: =AVERAGEIF('Final Project Dataset'!F4:F253,A4,'Final Project Dataset'!N4:N253) -> 440.59562 | E4: =RANK(B4,$B$2:$B$11,0) -> 8 | G4: Least Purchased Product | H4: =INDEX(A2:A11,MATCH(MIN(B2:B11),B2:B11,0)) -> Coffee Maker
A5: Monitor | B5: =COUNTIF('Final Project Dataset'!F5:F254,A5) -> 24 | C5: =SUMIF('Final Project Dataset'!F5:F254,A5,'Final Project Dataset'!N5:N254) -> 20499.18 | D5: =AVERAGEIF('Final Project Dataset'!F5:F254,A5,'Final Project Dataset'!N5:N254) -> 854.1325 | E5: =RANK(B5,$B$2:$B$11,0) -> 6 | G5: Least Purchased Count | H5: =MIN(B2:B11) -> 14
A6: Keyboard | B6: =COUNTIF('Final Project Dataset'!F6:F255,A6) -> 34 | C6: =SUMIF('Final Project Dataset'!F6:F255,A6,'Final Project Dataset'!N6:N255) -> 8009.11 | D6: =AVERAGEIF('Final Project Dataset'!F6:F255,A6,'Final Project Dataset'!N6:N255) -> 235.56206 | E6: =RANK(B6,$B$2:$B$11,0) -> 1 | G6: Highest Revenue Product | H6: =INDEX(A2:A11,MATCH(MAX(C2:C11),C2:C11,0)) -> Laptop
